Workbook

Sheet 明细
A1: 第20届亚运会（爱知·名古屋 2026）— 2026-10-02 金牌明细（第13比赛日，全天已结束）
A3: 序号 | B3: 大项 | C3: 分项 | D3: 冠军代表团 | E3: 冠军/队伍 | F3: 备注
A4: 1 | B4: 拳击 | C4: 男子55公斤级 | D4: 日本 | E4: 山口来生 | F4: 3:2 胜菲律宾帕阿兰，日本52年来该级别首金
A5: 2 | B5: 拳击 | C5: 男子60公斤级 | D5: 乌兹别克斯坦 | E5: 阿卜杜马利克·卡洛科霍夫
A6: 3 | B6: 拳击 | C6: 男子70公斤级 | D6: 哈萨克斯坦 | E6: 托列汗·萨贝尔汗 | F6: 5:0 胜约旦伊沙伊什
A7: 4 | B7: 拳击 | C7: 男子80公斤级 | D7: 印度 | E7: 安库什·潘加勒 | F7: 4:0 胜韩国金旻成
A8: 5 | B8: 拳击 | C8: 男子90公斤级 | D8: 乌兹别克斯坦 | E8: 图拉别克·哈比布拉耶夫 | F8: 5:0 胜中国韩雪贞
A9: 6 | B9: 拳击 | C9: 男子90公斤以上级 | D9: 哈萨克斯坦 | E9: 艾别克·奥拉尔巴耶
A10: 7 | B10: 拳击 | C10: 女子51公斤级 | D10: 中国 | E10: 吴愉 | F10: 5:0 完胜越南选手
A11: 8 | B11: 拳击 | C11: 女子54公斤级 | D11: 泰国 | E11: 纳特尼查·琼蓬格朗 | F11: 决赛胜朝鲜朴春美
A12: 9 | B12: 拳击 | C12: 女子60公斤级 | D12: 中国台北 | E12: 林郁婷 | F12: 决赛胜中国杨成宇
A13: 10 | B13: 拳击 | C13: 女子65公斤级 | D13: 印度 | E13: 帕维恩·胡达 | F13: 3:2 胜中国台北陈念琴
A14: 11 | B14: 拳击 | C14: 女子75公斤级 | D14: 印度 | E14: 洛夫利娜·博尔戈哈因 | F14: 5:0 胜中国鲍子怡
A15: 12 | B15: 帆船 | C15: 男子ILCA 7级 | D15: 韩国 | E15: 河智旻
A16: 13 | B16: 帆船 | C16: 女子49erFX级 | D16: 日本 | E16: 田中美咲/长永濑世拉
A17: 14 | B17: 帆船 | C17: 混合470级 | D17: 日本 | E17: 磯崎哲也/关友里惠
A18: 15 | B18: 帆船 | C18: 男子iQFoil级 | D18: 中国 | E18: 毕坤 | F18: 10月3日风小取消，按2日末轮名次判金
A19: 16 | B19: 帆船 | C19: 女子iQFoil级 | D19: 中国 | E19: 李文琪 | F19: 10月3日风小取消，按2日末轮名次判金
A20: 17 | B20: 摔跤-自由式 | C20: 男子65公斤级 | D20: 印度 | E20: 苏吉特·卡尔卡尔 | F20: 10:9 逆转胜塔吉克斯坦库迪耶夫
A21: 18 | B21: 摔跤-自由式 | C21: 男子86公斤级 | D21: 伊朗 | E21: 穆罕默德·诺霍迪 | F21: 9:6 胜日本石黑隼人
A22: 19 | B22: 摔跤-自由式 | C22: 男子125公斤级 | D22: 伊朗 | E22: 阿米尔侯赛因·扎雷 | F22: 12:2 胜中国布和额尔顿，卫冕
A23: 20 | B23: 摔跤-自由式 | C23: 女子50公斤级 | D23: 日本 | E23: 须崎优衣 | F23: 决赛零封朝鲜选手
A24: 21 | B24: 摔跤-自由式 | C24: 女子76公斤级 | D24: 日本 | E24: 镜和翔 | F24: 5:1 胜哈萨克斯坦选手
A25: 22 | B25: 柔道 | C25: 男子90公斤级 | D25: 日本 | E25: 冈田陆 | F25: 金分技取胜
A26: 23 | B26: 柔道 | C26: 男子100公斤级 | D26: 日本 | E26: 增地辽太郎 | F26: 一本取胜
A27: 24 | B27: 柔道 | C27: 女子78公斤级 | D27: 日本 | E27: 杉村美寿希 | F27: 反则胜韩国金敏周
A28: 25 | B28: 柔道 | C28: 女子78公斤以上级 | D28: 中国 | E28: 牛馨然
A29: 26 | B29: 柔道 | C29: 男子100公斤以上级 | D29: 乌兹别克斯坦 | E29: 图罗博耶夫·穆扎法尔别克
A30: 27 | B30: 跆拳道 | C30: 男子-58公斤级 | D30: 乌兹别克斯坦 | E30: 贾苏尔贝克·贾伊苏诺夫
A31: 28 | B31: 跆拳道 | C31: 男子-80公斤级 | D31: 哈萨克斯坦 | E31: 塔米尔兰·特勒乌列斯
A32: 29 | B32: 跆拳道 | C32: 女子-49公斤级 | D32: 中国 | E32: 马静月
A33: 30 | B33: 跆拳道 | C33: 女子-67公斤级 | D33: 伊朗 | E33: 萨加尔·莫拉迪
A34: 31 | B34: 场地自行车 | C34: 男子凯林赛 | D34: 马来西亚 | E34: 穆赫德·阿兹祖哈斯尼·阿旺 | F34: 决赛夺冠
A35: 32 | B35: 场地自行车 | C35: 男子麦迪逊赛 | D35: 日本 | E35: 窪木一茂/儿岛直树 | F35: 76分夺金
A36: 33 | B36: 场地自行车 | C36: 女子争先赛 | D36: 中国 | E36: 苑丽颖 | F36: 胜日本佐藤水菜
A37: 34 | B37: 场地自行车 | C37: 女子全能赛 | D37: 日本 | E37: 梶原悠未 | F37: 136分，三连冠
A38: 35 | B38: 射箭 | C38: 反曲弓混合团体 | D38: 中国 | E38: 李梦麒/朱静怡 | F38: 5:3 胜印度，获洛杉矶奥运席位
A39: 36 | B39: 射箭 | C39: 反曲弓男子团体 | D39: 韩国 | E39: 韩国男子团体 | F39: 5:1 胜印度
A40: 37 | B40: 射箭 | C40: 反曲弓女子团体 | D40: 印度 | E40: 安基塔·巴卡特/蒂尔蒂·夏尔玛/库姆库姆·莫霍德 | F40: 5:3 胜韩国，印度首夺该项目亚运金
A41: 38 | B41: 皮划艇激流回旋 | C41: 男子皮艇越野 | D41: 日本 | E41: 田中雄己
...

Sheet 透视
A1: 透视汇总 — 2026-10-02 金牌（所有汇总数字均为公式，引用『明细』页）
A3: 一、按大项汇总
A4: 大项 | B4: 金牌数
A5: 拳击 | B5: =COUNTIF(明细!$B$4:$B$54,A5)
A6: 帆船 | B6: =COUNTIF(明细!$B$4:$B$54,A6)
A7: 摔跤-自由式 | B7: =COUNTIF(明细!$B$4:$B$54,A7)
A8: 柔道 | B8: =COUNTIF(明细!$B$4:$B$54,A8)
A9: 跆拳道 | B9: =COUNTIF(明细!$B$4:$B$54,A9)
A10: 场地自行车 | B10: =COUNTIF(明细!$B$4:$B$54,A10)
A11: 射箭 | B11: =COUNTIF(明细!$B$4:$B$54,A11)
A12: 皮划艇激流回旋 | B12: =COUNTIF(明细!$B$4:$B$54,A12)
A13: 柔术 | B13: =COUNTIF(明细!$B$4:$B$54,A13)
A14: 壁球 | B14: =COUNTIF(明细!$B$4:$B$54,A14)
A15: 网球 | B15: =COUNTIF(明细!$B$4:$B$54,A15)
A16: 电子竞技 | B16: =COUNTIF(明细!$B$4:$B$54,A16)
... A20: 曲棍球 | B20: =COUNTIF(明细!$B$4:$B$54,A20)
A21: 合计 | B21: =SUM(B5:B20)
A23: 二、按代表团（国家/地区）汇总
A24: 代表团 | B24: 金牌数
A25: 中国 | B25: =COUNTIF(明细!$D$4:$D$54,A25)
A26: 日本 | B26: =COUNTIF(明细!$D$4:$D$54,A26)
A27: 韩国 | B27: =COUNTIF(明细!$D$4:$D$54,A27)
A28: 印度 | B28: =COUNTIF(明细!$D$4:$D$54,A28)
A29: 乌兹别克斯坦 | B29: =COUNTIF(明细!$D$4:$D$54,A29)
A30: 哈萨克斯坦 | B30: =COUNTIF(明细!$D$4:$D$54,A30)
A31: 伊朗 | B31: =COUNTIF(明细!$D$4:$D$54,A31)
A32: 泰国 | B32: =COUNTIF(明细!$D$4:$D$54,A32)
A33: 马来西亚 | B33: =COUNTIF(明细!$D$4:$D$54,A33)
A34: 中国台北 | B34: =COUNTIF(明细!$D$4:$D$54,A34)
A35: 阿联酋 | B35: =COUNTIF(明细!$D$4:$D$54,A35)
A36: 菲律宾 | B36: =COUNTIF(明细!$D$4:$D$54,A36)
A37: 沙特阿拉伯 | B37: =COUNTIF(明细!$D$4:$D$54,A37)
A38: 合计 | B38: =SUM(B25:B37)
A40: 三、口径校验
A41: 校验项 | B41: 数值
A42: 明细行数（COUNTA 公式） | B42: =COUNTA(明细!$A$4:$A$54)
A43: 按大项合计 | B43: =B21
A44: 按代表团合计 | B44: =B38
A45: 任务口径应产金数（用户给定） | B45: 51
A46: 四方是否一致 | B46: =IF(AND(B42=B43,B43=B44,B44=B45),"一致","不一致")

Sheet 口径说明
A1: 口径说明
A3: 1. 统计对象：第20届亚洲运动会（爱知·名古屋 2026）2026-10-02（第13比赛日，星期五）当日决出的全部金牌；当日为本届产金最多的一天，按官方赛程全天共决出 51 枚金牌。
A4: 2. 当日为全天已结束状态，按赛后最终成绩采集（多来源交叉核验，见『数据来源』页）。
A5: 3. 金牌归属判定：以各单项决赛最终结果为准；团体/双人项目按代表团计 1 枚金牌。
A6: 4. 代表团按 NOC 口径统计；中国香港、中国台北等均以代表团名称列示（中国香港当日未夺金）。
A7: 5. 当日金牌按大项分布（与官方当日赛程一致）：拳击11、帆船5、摔跤5、柔道5、跆拳道4、场地自行车4、射箭3、皮划艇激流回旋2、柔术3、壁球2、网球2、电子竞技1、足球1、虚拟跆拳道1（本届新增小项）、沙滩排球1、曲棍球1，合计 51。
A8: 6. 帆船 iQFoil（水翼帆板）男、女两级：因10月3日风力不足取消后续比赛，按10月2日末轮结束后名次定格判金（奖牌仪式于次日举行），故计入10月2日产出；其余帆船三级（ILCA7、49erFX、470混合）当日决赛正常进行。
A9: 7. 当日部分代表团产金数（供核对）：日本13、中国9（含上述帆船2项按名次定格判金；若按奖牌仪式当日口径中国为7）、韩国3、印度6、乌兹别克斯坦4、哈萨克斯坦3、伊朗3、马来西亚3、泰国2、阿联酋2、中国台北1、菲律宾1、沙特阿拉伯1。
A10: 8. 透视页所有汇总数字均为 Excel 公式（COUNTIF/SUM/COUNTA/IF）引用『明细』页实时计算，严禁且未手写任何汇总常数；透视页校验区对『明细行数、按大项合计、按代表团合计、任务口径51』四方相互核对，结果应为『一致』。
A11: 9. 任务口径应产生金牌总数 = 51（用户给定）。
A12: 10. 工作簿生成时间：2026-10-07（UTC）；生成环境：Python 3 + openpyxl。

Sheet 数据来源
A1: 数据来源（2026-10-07 采集，赛后多源交叉核验）
A3: # | B3: 来源 | C3: 说明 | D3: 链接
A4: 1 | B4: 名古屋亚运会官方成绩系统（Bornan） | C4: 各单项决赛官方结果 | D4: https://results.asiangames2026.org/
A5: 2 | B5: 爱知·名古屋 2026 组委会官网 | C5: 官方赛程：10月2日 16 个大项决出 51 金及其分布 | D5: https://www.aichi-nagoya2026.org/sports/
A6: 3 | B6: 日本奥委会（JOC）当日结果页 | C6: 日本队 10月2日全部结果（当日 13 金逐项核实） | D6: https://www.joc.or.jp/games/asia/2026/schedule/result_1002.html
A7: 4 | B7: World Boxing（世界拳击） | C7: 拳击 11 个级别决赛全部结果 | D7: https://worldboxing.org/eleven-champions-crowned-as-india-top-aichi-nagoya-2026-asian-games-boxing-medal-table/
A8: 5 | B8: Olympics.com 亚运专题 | C8: 印度当日 6 金战报（摔跤/拳击/女曲/射箭女团） | D8: https://www.olympics.com/en/news/asian-games-2026-live-scores-updates-results-india-october-2
A9: 6 | B9: KhelNow 第13日奖牌综述 | C9: 当日各国金牌归属（拳击/柔道/跆拳道/自行车/皮划艇/网球/电竞等） | D9: https://khelnow.com/asian-games/medal-tally-october-2-asian-games-202610
A10: 7 | B10: 央视网亚运专题 / 搜狐体育 | C10: 中国代表团当日夺金明细与奖牌榜日增量 | D10: https://yayun.cctv.com/2026/dateschedule/index.shtml
A11: 8 | B11: United World Wrestling（UWW） | C11: 摔跤第3日（10月2日）5 个级别决赛结果 | D11: https://uww.org/articles/asian-games-2026-wrestling-day-3-highlights-susaki-sujeet-zare-win-gold
A12: 9 | B12: 共同社（Kyodo） | C12: 女足决赛（日本点球胜朝鲜，三连冠） | D12: https://english.kyodonews.net/articles/-/87069
A13: 10 | B13: World Squash | C13: 壁球男/女团体决赛（马来西亚双金） | D13: https://www.worldsquash.sport/historic-gold-medal-double-for-malaysia-at-2026-asian-games-teams/
A14: 11 | B14: Asian Sailing / Wikipedia 帆船页 | C14: 帆船 5 个级别结果及 iQFoil 名次定格说明 | D14: https://www.asiansailing.org/asian-games-final-day-report/
A15: 12 | B15: Sharjah24 / Khaleej Times（阿联酋） | C15: 柔术当日金牌（阿联酋 2 金） | D15: https://sharjah24.ae/en/Articles/2026/10/02/AL011
... A18: 15 | B18: Wikipedia: 2026 Asian Games medal table | C18: 各代表团累计金牌数日增量交叉核验 | D18: https://en.wikipedia.org/wiki/2026_Asian_Games_medal_table
